Workbook

Sheet Navigation
C6: TALENTS APARTMENT
C7: Accounting Information System
C8: ...home away from home
C11: DAILY INPUT
C12: Record Income | E12: All revenue transactions | H12: →
C13: Record Expenses | E13: Non-salary expense transactions | H13: →
C14: Staff Salaries | E14: Monthly company payroll totals | H14: →
C15: Budget & Targets | E15: Monthly budget vs actual variance | H15: →
C17: REPORTS & ANALYSIS
C18: Executive Dashboard | E18: KPIs + monthly P&L matrix | H18: →
C19: Charts & Analytics | E19: 6 interactive charts with location filter | H19: →
C20: General Ledger | E20: Double-entry records | H20: →
C21: Profit & Loss | E21: Annual income statement | H21: →
C22: Cash Flow | E22: Cash movements summary | H22: →
C23: Balance Sheet | E23: Financial position snapshot | H23: →
C24: Trial Balance | E24: Debit/credit verification | H24: →
C26: SYSTEM SETTINGS
C27: Chart of Accounts | E27: Account code structure | H27: →
C28: Dropdown Lists | E28: Master control for ALL dropdowns | H28: →
C29: Employee Records | E29: Staff info & payroll rates | H29: →

Sheet Revenue_Log
B2: Revenue Log
B3: Record all income transactions
A4: TOTAL: | H4: =SUBTOTAL(9,H6:H5000)
A5: Date | B5: Location | C5: Unit Name | D5: Account | E5: Description | F5: Txn ID | G5: Payment Method | H5: Amount
A6: 45299 | B6: Agbowo | C6: Anooore 1 | D6: Room Revenue | E6: Booking - Anooore 1 | F6: R0001 | G6: Bank Transfer | H6: 196558
A7: 45299 | B7: Agbowo | C7: Anooore 1 | D7: Extra Charges | E7: TV rental | F7: R0002 | G7: Cash | H7: 10000
A8: 45308 | B8: Agbowo | C8: Vine 1 | D8: Room Revenue | E8: Booking - Vine 1 | F8: R0003 | G8: Cash | H8: 176948
A9: 45310 | B9: Agbowo | C9: Vine 2 | D9: Room Revenue | E9: Booking - Vine 2 | F9: R0004 | G9: POS | H9: 354033
A10: 45310 | B10: Agbowo | C10: Vine 2 | D10: Form & Legal Fees | E10: Registration form fee | F10: R0005 | G10: Cash | H10: 5000
A11: 45298 | B11: Agbowo | C11: Provision Shop | D11: Room Revenue | E11: Booking - Provision Shop | F11: R0006 | G11: POS | H11: 298616
A12: 45298 | B12: Agbowo | C12: Provision Shop | D12: Extra Charges | E12: TV rental | F12: R0007 | G12: Cash | H12: 25000
A13: 45315 | B13: Agbowo | C13: Salon | D13: Room Revenue | E13: Booking - Salon | F13: R0008 | G13: Mobile Transfer | H13: 331695
A14: 45312 | B14: UI | C14: Anooore 2 | D14: Room Revenue | E14: Booking - Anooore 2 | F14: R0009 | G14: POS | H14: 479317
A15: 45294 | B15: UI | C15: Scholar | D15: Room Revenue | E15: Booking - Scholar | F15: R0010 | G15: Bank Transfer | H15: 263653
A16: 45303 | B16: UI | C16: Scholar 2 | D16: Room Revenue | E16: Booking - Scholar 2 | F16: R0011 | G16: Bank Transfer | H16: 291415
A17: 45297 | B17: UI | C17: Kollege | D17: Room Revenue | E17: Booking - Kollege | F17: R0012 | G17: Bank Transfer | H17: 191592

Sheet Expenses_Log
B2: Expenses Log
B3: Non-salary expenses (salaries tracked in Staff_Salaries sheet)
A4: TOTAL: | G4: =SUBTOTAL(9,G6:G5000)
A5: Date | B5: Location | C5: Category | D5: Vendor/Staff | E5: Department | F5: Description | G5: Amount | H5: Payment Method | I5: Acct Code
A6: 45292 | B6: Agbowo | C6: Loans & Advances | D6: Stanbic Bank | E6: Accounts | F6: Monthly loan repayment | G6: 200000 | H6: Bank Transfer
A7: 45294 | B7: Agbowo | C7: Maintenance | D7: Dayo Contractor | E7: Maintenance | F7: Paint touch-up | G7: 41000 | H7: Cash
A8: 45294 | B8: UI | C8: Utilities | D8: Waste Mgt Co | E8: Admin | F8: Water bill | G8: 41000 | H8: Bank Transfer
A9: 45295 | B9: UI | C9: Maintenance | D9: Plumber Bayo | E9: Maintenance | F9: Paint touch-up | G9: 24000 | H9: Cash
A10: 45300 | B10: Agbowo | C10: Construction | D10: Mr Taiwo | E10: Project | F10: Mason work | G10: 27000 | H10: Cash
A11: 45300 | B11: Agbowo | C11: Maintenance | D11: Plumber Bayo | E11: Maintenance | F11: Door/lock repair | G11: 10000 | H11: Cash
A12: 45302 | B12: UI | C12: Administrative | D12: Office Mart | E12: Admin | F12: Insurance premium | G12: 8000 | H12: Cash
A13: 45305 | B13: Agbowo | C13: Construction | D13: Engr Segun | E13: Project | F13: Tiling | G13: 48000 | H13: Cash

Sheet Staff_Salaries
B2: Staff Salaries
B3: Monthly company payroll — feeds into total expenses
A4: ANNUAL PAYROLL TOTAL: | E4: =SUMPRODUCT((Staff_Salaries!A6:A5000=Dashboard!$B$1)*(Staff_Salaries!E6:E5000)) | F4: Staff count: | G4: =COUNTA(Employee_Data!C6:C5000)
A5: Year | B5: Month | C5: Description | D5: Staff Count | E5: Total Paid | F5: Payment Method | G5: Notes
A6: 2024 | B6: January | C6: Monthly staff payroll | D6: 12 | E6: 407669 | F6: Bank Transfer
A7: 2024 | B7: February | C7: Monthly staff payroll | D7: 12 | E7: 406109 | F7: Bank Transfer
A8: 2024 | B8: March | C8: Monthly staff payroll | D8: 12 | E8: 401121 | F8: Bank Transfer
A9: 2024 | B9: April | C9: Monthly staff payroll | D9: 12 | E9: 411259 | F9: Bank Transfer
A10: 2024 | B10: May | C10: Monthly staff payroll | D10: 12 | E10: 411302 | F10: Bank Transfer
A11: 2024 | B11: June | C11: Monthly staff payroll | D11: 12 | E11: 407037 | F11: Bank Transfer
A12: 2024 | B12: July | C12: Monthly staff payroll | D12: 12 | E12: 412015 | F12: Bank Transfer
A13: 2024 | B13: August | C13: Monthly staff payroll | D13: 12 | E13: 403739 | F13: Bank Transfer
A14: 2024 | B14: September | C14: Monthly staff payroll | D14: 12 | E14: 397707 | F14: Bank Transfer
A15: 2024 | B15: October | C15: Monthly staff payroll | D15: 12 | E15: 408910 | F15: Bank Transfer
A16: 2024 | B16: November | C16: Monthly staff payroll | D16: 12 | E16: 397586 | F16: Bank Transfer
A17: 2024 | B17: December | C17: Monthly staff payroll | D17: 12 | E17: 409110 | F17: Bank Transfer

Sheet Budget
B2: Annual Budget
B3: Monthly targets — Variance = Budget minus Actual
B6: REVENUE BUDGET
B7: Category | C7: Jan | F7: Feb | I7: Mar | L7: Apr | O7: May | R7: Jun | U7: Jul | X7: Aug | AA7: Sep | AD7: Oct | AG7: Nov | AJ7: Dec | AM7: YEAR TOTAL
C8: Budget | D8: Actual | E8: Var | F8: Budget | G8: Actual | H8: Var | I8: Budget | J8: Actual | K8: Var | L8: Budget | M8: Actual | N8: Var | O8: Budget | P8: Actual | Q8: Var | R8: Budget | S8: Actual | T8: Var | U8: Budget | V8: Actual | W8: Var | X8: Budget | Y8: Actual | Z8: Var | AA8: Budget | AB8: Actual | AC8: Var | AD8: Budget | AE8: Actual | AF8: Var | AG8: Budget | AH8: Actual | AI8: Var | AJ8: Budget | AK8: Actual | AL8: Var | AM8: Budget | AN8: Actual | AO8: Var
B9: Room Revenue | C9: 3200000 | D9: =SUMPRODUCT((YEAR(Revenue_Log!A6:A5000)=Dashboard!$B$1)*(MONTH(Revenue_Log!A6:A5000)=1)*(Revenue_Log!D6:D5000="Room Revenue")*(Revenue_Log!H6:H5000)) | E9: =IFERROR(D9-C9,"—") | F9: 3000000 | G9: =SUMPRODUCT((YEAR(Revenue_Log!A6:A5000)=Dashboard!$B$1)*(MONTH(Revenue_Log!A6:A5000)=2)*(Revenue_Log!D6:D5000="Room Revenue")*(Revenue_Log!H6:H5000)) | H9: =IFERROR(G9-F9,"—") | I9: 2600000 | J9: =SUMPRODUCT((YEAR(Revenue_Log!A6:A5000)=Dashboard!$B$1)*(MONTH(Revenue_Log!A6:A5000)=3)*(Revenue_Log!D6:D5000="Room Revenue")*(Revenue_Log!H6:H5000)) | K9: =IFERROR(J9-I9,"—") | L9: 2400000 | M9: =SUMPRODUCT((YEAR(Revenue_Log!A6:A5000)=Dashboard!$B$1)*(MONTH(Revenue_Log!A6:A5000)=4)*(Revenue_Log!D6:D5000="Room Revenue")*(Revenue_Log!H6:H5000)) | N9: =IFERROR(M9-L9,"—") | O9: 2400000 | P9: =SUMPRODUCT((YEAR(Revenue_Log!A6:A5000)=Dashboard!$B$1)*(MONTH(Revenue_Log!A6:A5000)=5)*(Revenue_Log!D6:D5000="Room Revenue")*(Revenue_Log!H6:H5000)) | Q9: =IFERROR(P9-O9,"—") | R9: 1800000 | S9: =SUMPRODUCT((YEAR(Revenue_Log!A6:A5000)=Dashboard!$B$1)*(MONTH(Revenue_Log!A6:A5000)=6)*(Revenue_Log!D6:D5000="Room Revenue")*(Revenue_Log!H6:H5000)) | T9: =IFERROR(S9-R9,"—") | U9: 1600000 | V9: =SUMPRODUCT((YEAR(Revenue_Log!A6:A5000)=Dashboard!$B$1)*(MONTH(Revenue_Log!A6:A5000)=7)*(Revenue_Log!D6:D5000="Room Revenue")*(Revenue_Log!H6:H5000)) | W9: =IFERROR(V9-U9,"—") | X9: 1600000 | Y9: =SUMPRODUCT((YEAR(Revenue_Log!A6:A5000)=Dashboard!$B$1)*(MONTH(Revenue_Log!A6:A5000)=8)*(Revenue_Log!D6:D5000="Room Revenue")*(Revenue_Log!H6:H5000)) | Z9: =IFERROR(Y9-X9,"—") | AA9: 3200000 | AB9: =SUMPRODUCT((YEAR(Revenue_Log!A6:A5000)=Dashboard!$B$1)*(MONTH(Revenue_Log!A6:A5000)=9)*(Revenue_Log!D6:D5000="Room Revenue")*(Revenue_Log!H6:H5000)) | AC9: =IFERROR(AB9-AA9,"—") | AD9: 3200000 | AE9: =SUMPRODUCT((YEAR(Revenue_Log!A6:A5000)=Dashboard!$B$1)*(MONTH(Revenue_Log!A6:A5000)=10)*(Revenue_Log!D6:D5000="Room Revenue")*(Revenue_Log!H6:H5000)) | AF9: =IFERROR(AE9-AD9,"—") | AG9: 2800000 | AH9: =SUMPRODUCT((YEAR(Revenue_Log!A6:A5000)=Dashboard!$B$1)*(MONTH(Revenue_Log!A6:A5000)=11)*(Revenue_Log!D6:D5000="Room Revenue")*(Revenue_Log!H6:H5000)) | AI9: =IFERROR(AH9-AG9,"—") | AJ9: 2800000 | AK9: =SUMPRODUCT((YEAR(Revenue_Log!A6:A5000)=Dashboard!$B$1)*(MONTH(Revenue_Log!A6:A5000)=12)*(Revenue_Log!D6:D5000="Room Revenue")*(Revenue_Log!H6:H5000)) | AL9: =IFERROR(AK9-AJ9,"—") | AM9: =C9+F9+I9+L9+O9+R9+U9+X9+AA9+AD9+AG9+AJ9 | AN9: =D9+G9+J9+M9+P9+S9+V9+Y9+AB9+AE9+AH9+AK9 | AO9: =IFERROR(AN9-AM9,"—")
B10: Shop Rent | C10: 120000 | D10: =SUMPRODUCT((YEAR(Revenue_Log!A6:A5000)=Dashboard!$B$1)*(MONTH(Revenue_Log!A6:A5000)=1)*(Revenue_Log!D6:D5000="Shop Rent")*(Revenue_Log!H6:H5000)) | E10: =IFERROR(D10-C10,"—") | F10: 120000 | G10: =SUMPRODUCT((YEAR(Revenue_Log!A6:A5000)=Dashboard!$B$1)*(MONTH(Revenue_Log!A6:A5000)=2)*(Revenue_Log!D6:D5000="Shop Rent")*(Revenue_Log!H6:H5000)) | H10: =IFERROR(G10-F10,"—") | I10: 120000 | J10: =SUMPRODUCT((YEAR(Revenue_Log!A6:A5000)=Dashboard!$B$1)*(MONTH(Revenue_Log!A6:A5000)=3)*(Revenue_Log!D6:D5000="Shop Rent")*(Revenue_Log!H6:H5000)) | K10: =IFERROR(J10-I10,"—") | L10: 120000 | M10: =SUMPRODUCT((YEAR(Revenue_Log!A6:A5000)=Dashboard!$B$1)*(MONTH(Revenue_Log!A6:A5000)=4)*(Revenue_Log!D6:D5000="Shop Rent")*(Revenue_Log!H6:H5000)) | N10: =IFERROR(M10-L10,"—") | O10: 120000 | P10: =SUMPRODUCT((YEAR(Revenue_Log!A6:A5000)=Dashboard!$B$1)*(MONTH(Revenue_Log!A6:A5000)=5)*(Revenue_Log!D6:D5000="Shop Rent")*(Revenue_Log!H6:H5000)) | Q10: =IFERROR(P10-O10,"—") | R10: 120000 | S10: =SUMPRODUCT((YEAR(Revenue_Log!A6:A5000)=Dashboard!$B$1)*(MONTH(Revenue_Log!A6:A5000)=6)*(Revenue_Log!D6:D5000="Shop Rent")*(Revenue_Log!H6:H5000)) | T10: =IFERROR(S10-R10,"—") | U10: 120000 | V10: =SUMPRODUCT((YEAR(Revenue_Log!A6:A5000)=Dashboard!$B$1)*(MONTH(Revenue_Log!A6:A5000)=7)*(Revenue_Log!D6:D5000="Shop Rent")*(Revenue_Log!H6:H5000)) | W10: =IFERROR(V10-U10,"—") | X10: 120000 | Y10: =SUMPRODUCT((YEAR(Revenue_Log!A6:A5000)=Dashboard!$B$1)*(MONTH(Revenue_Log!A6:A5000)=8)*(Revenue_Log!D6:D5000="Shop Rent")*(Revenue_Log!H6:H5000)) | Z10: =IFERROR(Y10-X10,"—") | AA10: 120000 | AB10: =SUMPRODUCT((YEAR(Revenue_Log!A6:A5000)=Dashboard!$B$1)*(MONTH(Revenue_Log!A6:A5000)=9)*(Revenue_Log!D6:D5000="Shop Rent")*(Revenue_Log!H6:H5000)) | AC10: =IFERROR(AB10-AA10,"—") | AD10: 120000 | AE10: =SUMPRODUCT((YEAR(Revenue_Log!A6:A5000)=Dashboard!$B$1)*(MONTH(Revenue_Log!A6:A5000)=10)*(Revenue_Log!D6:D5000="Shop Rent")*(Revenue_Log!H6:H5000)) | AF10: =IFERROR(AE10-AD10,"—") | AG10: 120000 | AH10: =SUMPRODUCT((YEAR(Revenue_Log!A6:A5000)=Dashboard!$B$1)*(MONTH(Revenue_Log!A6:A5000)=11)*(Revenue_Log!D6:D5000="Shop Rent")*(Revenue_Log!H6:H5000)) | AI10: =IFERROR(AH10-AG10,"—") | AJ10: 120000 | AK10: =SUMPRODUCT((YEAR(Revenue_Log!A6:A5000)=Dashboard!$B$1)*(MONTH(Revenue_Log!A6:A5000)=12)*(Revenue_Log!D6:D5000="Shop Rent")*(Revenue_Log!H6:H5000)) | AL10: =IFERROR(AK10-AJ10,"—") | AM10: =C10+F10+I10+L10+O10+R10+U10+X10+AA10+AD10+AG10+AJ10 | AN10: =D10+G10+J10+M10+P10+S10+V10+Y10+AB10+AE10+AH10+AK10 | AO10: =IFERROR(AN10-AM10,"—")
B11: Caution Fee Income | C11: 75000 | D11: =SUMPRODUCT((YEAR(Revenue_Log!A6:A5000)=Dashboard!$B$1)*(MONTH(Revenue_Log!A6:A5000)=1)*(Revenue_Log!D6:D5000="Caution Fee Income")*(Revenue_Log!H6:H5000)) | E11: =IFERROR(D11-C11,"—") | F11: 50000 | G11: =SUMPRODUCT((YEAR(Revenue_Log!A6:A5000)=Dashboard!$B$1)*(MONTH(Revenue_Log!A6:A5000)=2)*(Revenue_Log!D6:D5000="Caution Fee Income")*(Revenue_Log!H6:H5000)) | H11: =IFERROR(G11-F11,"—") | I11: 50000 | J11: =SUMPRODUCT((YEAR(Revenue_Log!A6:A5000)=Dashboard!$B$1)*(MONTH(Revenue_Log!A6:A5000)=3)*(Revenue_Log!D6:D5000="Caution Fee Income")*(Revenue_Log!H6:H5000)) | K11: =IFERROR(J11-I11,"—") | L11: 50000 | M11: =SUMPRODUCT((YEAR(Revenue_Log!A6:A5000)=Dashboard!$B$1)*(MONTH(Revenue_Log!A6:A5000)=4)*(Revenue_Log!D6:D5000="Caution Fee Income")*(Revenue_Log!H6:H5000)) | N11: =IFERROR(M11-L11,"—") | O11: 50000 | P11: =SUMPRODUCT((YEAR(Revenue_Log!A6:A5000)=Dashboard!$B$1)*(MONTH(Revenue_Log!A6:A5000)=5)*(Revenue_Log!D6:D5000="Caution Fee Income")*(Revenue_Log!H6:H5000)) | Q11: =IFERROR(P11-O11,"—") | R11: 50000 | S11: =SUMPRODUCT((YEAR(Revenue_Log!A6:A5000)=Dashboard!$B$1)*(MONTH(Revenue_Log!A6:A5000)=6)*(Revenue_Log!D6:D5000="Caution Fee Income")*(Revenue_Log!H6:H5000)) | T11: =IFERROR(S11-R11,"—") | U11: 50000 | V11: =SUMPRODUCT((YEAR(Revenue_Log!A6:A5000)=Dashboard!$B$1)*(MONTH(Revenue_Log!A6:A5000)=7)*(Revenue_Log!D6:D5000="Caution Fee Income")*(Revenue_Log!H6:H5000)) | W11: =IFERROR(V11-U11,"—") | X11: 50000 | Y11: =SUMPRODUCT((YEAR(Revenue_Log!A6:A5000)=Dashboard!$B$1)*(MONTH(Revenue_Log!A6:A5000)=8)*(Revenue_Log!D6:D5000="Caution Fee Income")*(Revenue_Log!H6:H5000)) | Z11: =IFERROR(Y11-X11,"—") | AA11: 75000 | AB11: =SUMPRODUCT((YEAR(Revenue_Log!A6:A5000)=Dashboard!$B$1)*(MONTH(Revenue_Log!A6:A5000)=9)*(Revenue_Log!D6:D5000="Caution Fee Income")*(Revenue_Log!H6:H5000)) | AC11: =IFERROR(AB11-AA11,"—") | AD11: 75000 | AE11: =SUMPRODUCT((YEAR(Revenue_Log!A6:A5000)=Dashboard!$B$1)*(MONTH(Revenue_Log!A6:A5000)=10)*(Revenue_Log!D6:D5000="Caution Fee Income")*(Revenue_Log!H6:H5000)) | AF11: =IFERROR(AE11-AD11,"—") | AG11: 50000 | AH11: =SUMPRODUCT((YEAR(Revenue_Log!A6:A5000)=Dashboard!$B$1)*(MONTH(Revenue_Log!A6:A5000)=11)*(Revenue_Log!D6:D5000="Caution Fee Income")*(Revenue_Log!H6:H5000)) | AI11: =IFERROR(AH11-AG11,"—") | AJ11: 50000 | AK11: =SUMPRODUCT((YEAR(Revenue_Log!A6:A5000)=Dashboard!$B$1)*(MONTH(Revenue_Log!A6:A5000)=12)*(Revenue_Log!D6:D5000="Caution Fee Income")*(Revenue_Log!H6:H5000)) | AL11: =IFERROR(AK11-AJ11,"—") | AM11: =C11+F11+I11+L11+O11+R11+U11+X11+AA11+AD11+AG11+AJ11 | AN11: =D11+G11+J11+M11+P11+S11+V11+Y11+AB11+AE11+AH11+AK11 | AO11: =IFERROR(AN11-AM11,"—")
B12: Extra Charges | C12: 150000 | D12: =SUMPRODUCT((YEAR(Revenue_Log!A6:A5000)=Dashboard!$B$1)*(MONTH(Revenue_Log!A6:A5000)=1)*(Revenue_Log!D6:D5000="Extra Charges")*(Revenue_Log!H6:H5000)) | E12: =IFERROR(D12-C12,"—") | F12: 130000 | G12: =SUMPRODUCT((YEAR(Revenue_Log!A6:A5000)=Dashboard!$B$1)*(MONTH(Revenue_Log!A6:A5000)=2)*(Revenue_Log!D6:D5000="Extra Charges")*(Revenue_Log!H6:H5000)) | H12: =IFERROR(G12-F12,"—") | I12: 110000 | J12: =SUMPRODUCT((YEAR(Revenue_Log!A6:A5000)=Dashboard!$B$1)*(MONTH(Revenue_Log!A6:A5000)=3)*(Revenue_Log!D6:D5000="Extra Charges")*(Revenue_Log!H6:H5000)) | K12: =IFERROR(J12-I12,"—") | L12: 100000 | M12: =SUMPRODUCT((YEAR(Revenue_Log!A6:A5000)=Dashboard!$B$1)*(MONTH(Revenue_Log!A6:A5000)=4)*(Revenue_Log!D6:D5000="Extra Charges")*(Revenue_Log!H6:H5000)) | N12: =IFERROR(M12-L12,"—") | O12: 100000 | P12: =SUMPRODUCT((YEAR(Revenue_Log!A6:A5000)=Dashboard!$B$1)*(MONTH(Revenue_Log!A6:A5000)=5)*(Revenue_Log!D6:D5000="Extra Charges")*(Revenue_Log!H6:H5000)) | Q12: =IFERROR(P12-O12,"—") | R12: 80000 | S12: =SUMPRODUCT((YEAR(Revenue_Log!A6:A5000)=Dashboard!$B$1)*(MONTH(Revenue_Log!A6:A5000)=6)*(Revenue_Log!D6:D5000="Extra Charges")*(Revenue_Log!H6:H5000)) | T12: =IFERROR(S12-R12,"—") | U12: 70000 | V12: =SUMPRODUCT((YEAR(Revenue_Log!A6:A5000)=Dashboard!$B$1)*(MONTH(Revenue_Log!A6:A5000)=7)*(Revenue_Log!D6:D5000="Extra Charges")*(Revenue_Log!H6:H5000)) | W12: =IFERROR(V12-U12,"—") | X12: 70000 | Y12: =SUMPRODUCT((YEAR(Revenue_Log!A6:A5000)=Dashboard!$B$1)*(MONTH(Revenue_Log!A6:A5000)=8)*(Revenue_Log!D6:D5000="Extra Charges")*(Revenue_Log!H6:H5000)) | Z12: =IFERROR(Y12-X12,"—") | AA12: 150000 | AB12: =SUMPRODUCT((YEAR(Revenue_Log!A6:A5000)=Dashboard!$B$1)*(MONTH(Revenue_Log!A6:A5000)=9)*(Revenue_Log!D6:D5000="Extra Charges")*(Revenue_Log!H6:H5000)) | AC12: =IFERROR(AB12-AA12,"—") | AD12: 150000 | AE12: =SUMPRODUCT((YEAR(Revenue_Log!A6:A5000)=Dashboard!$B$1)*(MONTH(Revenue_Log!A6:A5000)=10)*(Revenue_Log!D6:D5000="Extra Charges")*(Revenue_Log!H6:H5000)) | AF12: =IFERROR(AE12-AD12,"—") | AG12: 110000 | AH12: =SUMPRODUCT((YEAR(Revenue_Log!A6:A5000)=Dashboard!$B$1)*(MONTH(Revenue_Log!A6:A5000)=11)*(Revenue_Log!D6:D5000="Extra Charges")*(Revenue_Log!H6:H5000)) | AI12: =IFERROR(AH12-AG12,"—") | AJ12: 110000 | AK12: =SUMPRODUCT((YEAR(Revenue_Log!A6:A5000)=Dashboard!$B$1)*(MONTH(Revenue_Log!A6:A5000)=12)*(Revenue_Log!D6:D5000="Extra Charges")*(Revenue_Log!H6:H5000)) | AL12: =IFERROR(AK12-AJ12,"—") | AM12: =C12+F12+I12+L12+O12+R12+U12+X12+AA12+AD12+AG12+AJ12 | AN12: =D12+G12+J12+M12+P12+S12+V12+Y12+AB12+AE12+AH12+AK12 | AO12: =IFERROR(AN12-AM12,"—")
B13: Form & Legal Fees | C13: 80000 | D13: =SUMPRODUCT((YEAR(Revenue_Log!A6:A5000)=Dashboard!$B$1)*(MONTH(Revenue_Log!A6:A5000)=1)*(Revenue_Log!D6:D5000="Form & Legal Fees")*(Revenue_Log!H6:H5000)) | E13: =IFERROR(D13-C13,"—") | F13: 60000 | G13: =SUMPRODUCT((YEAR(Revenue_Log!A6:A5000)=Dashboard!$B$1)*(MONTH(Revenue_Log!A6:A5000)=2)*(Revenue_Log!D6:D5000="Form & Legal Fees")*(Revenue_Log!H6:H5000)) | H13: =IFERROR(G13-F13,"—") | I13: 50000 | J13: =SUMPRODUCT((YEAR(Revenue_Log!A6:A5000)=Dashboard!$B$1)*(MONTH(Revenue_Log!A6:A5000)=3)*(Revenue_Log!D6:D5000="Form & Legal Fees")*(Revenue_Log!H6:H5000)) | K13: =IFERROR(J13-I13,"—") | L13: 45000 | M13: =SUMPRODUCT((YEAR(Revenue_Log!A6:A5000)=Dashboard!$B$1)*(MONTH(Revenue_Log!A6:A5000)=4)*(Revenue_Log!D6:D5000="Form & Legal Fees")*(Revenue_Log!H6:H5000)) | N13: =IFERROR(M13-L13,"—") | O13: 45000 | P13: =SUMPRODUCT((YEAR(Revenue_Log!A6:A5000)=Dashboard!$B$1)*(MONTH(Revenue_Log!A6:A5000)=5)*(Revenue_Log!D6:D5000="Form & Legal Fees")*(Revenue_Log!H6:H5000)) | Q13: =IFERROR(P13-O13,"—") | R13: 35000 | S13: =SUMPRODUCT((YEAR(Revenue_Log!A6:A5000)=Dashboard!$B$1)*(MONTH(Revenue_Log!A6:A5000)=6)*(Revenue_Log!D6:D5000="Form & Legal Fees")*(Revenue_Log!H6:H5000)) | T13: =IFERROR(S13-R13,"—") | U13: 30000 | V13: =SUMPRODUCT((YEAR(Revenue_Log!A6:A5000)=Dashboard!$B$1)*(MONTH(Revenue_Log!A6:A5000)=7)*(Revenue_Log!D6:D5000="Form & Legal Fees")*(Revenue_Log!H6:H5000)) | W13: =IFERROR(V13-U13,"—") | X13: 30000 | Y13: =SUMPRODUCT((YEAR(Revenue_Log!A6:A5000)=Dashboard!$B$1)*(MONTH(Revenue_Log!A6:A5000)=8)*(Revenue_Log!D6:D5000="Form & Legal Fees")*(Revenue_Log!H6:H5000)) | Z13: =IFERROR(Y13-X13,"—") | AA13: 80000 | AB13: =SUMPRODUCT((YEAR(Revenue_Log!A6:A5000)=Dashboard!$B$1)*(MONTH(Revenue_Log!A6:A5000)=9)*(Revenue_Log!D6:D5000="Form & Legal Fees")*(Revenue_Log!H6:H5000)) | AC13: =IFERROR(AB13-AA13,"—") | AD13: 80000 | AE13: =SUMPRODUCT((YEAR(Revenue_Log!A6:A5000)=Dashboard!$B$1)*(MONTH(Revenue_Log!A6:A5000)=10)*(Revenue_Log!D6:D5000="Form & Legal Fees")*(Revenue_Log!H6:H5000)) | AF13: =IFERROR(AE13-AD13,"—") | AG13: 60000 | AH13: =SUMPRODUCT((YEAR(Revenue_Log!A6:A5000)=Dashboard!$B$1)*(MONTH(Revenue_Log!A6:A5000)=11)*(Revenue_Log!D6:D5000="Form & Legal Fees")*(Revenue_Log!H6:H5000)) | AI13: =IFERROR(AH13-AG13,"—") | AJ13: 60000 | AK13: =SUMPRODUCT((YEAR(Revenue_Log!A6:A5000)=Dashboard!$B$1)*(MONTH(Revenue_Log!A6:A5000)=12)*(Revenue_Log!D6:D5000="Form & Legal Fees")*(Revenue_Log!H6:H5000)) | AL13: =IFERROR(AK13-AJ13,"—") | AM13: =C13+F13+I13+L13+O13+R13+U13+X13+AA13+AD13+AG13+AJ13 | AN13: =D13+G13+J13+M13+P13+S13+V13+Y13+AB13+AE13+AH13+AK13 | AO13: =IFERROR(AN13-AM13,"—")
B14: Other Income | C14: 0 | D14: =SUMPRODUCT((YEAR(Revenue_Log!A6:A5000)=Dashboard!$B$1)*(MONTH(Revenue_Log!A6:A5000)=1)*(Revenue_Log!D6:D5000="Other Income")*(Revenue_Log!H6:H5000)) | E14: =IFERROR(D14-C14,"—") | F14: 0 | G14: =SUMPRODUCT((YEAR(Revenue_Log!A6:A5000)=Dashboard!$B$1)*(MONTH(Revenue_Log!A6:A5000)=2)*(Revenue_Log!D6:D5000="Other Income")*(Revenue_Log!H6:H5000)) | H14: =IFERROR(G14-F14,"—") | I14: 0 | J14: =SUMPRODUCT((YEAR(Revenue_Log!A6:A5000)=Dashboard!$B$1)*(MONTH(Revenue_Log!A6:A5000)=3)*(Revenue_Log!D6:D5000="Other Income")*(Revenue_Log!H6:H5000)) | K14: =IFERROR(J14-I14,"—") | L14: 0 | M14: =SUMPRODUCT((YEAR(Revenue_Log!A6:A5000)=Dashboard!$B$1)*(MONTH(Revenue_Log!A6:A5000)=4)*(Revenue_Log!D6:D5000="Other Income")*(Revenue_Log!H6:H5000)) | N14: =IFERROR(M14-L14,"—") | O14: 0 | P14: =SUMPRODUCT((YEAR(Revenue_Log!A6:A5000)=Dashboard!$B$1)*(MONTH(Revenue_Log!A6:A5000)=5)*(Revenue_Log!D6:D5000="Other Income")*(Revenue_Log!H6:H5000)) | Q14: =IFERROR(P14-O14,"—") | R14: 0 | S14: =SUMPRODUCT((YEAR(Revenue_Log!A6:A5000)=Dashboard!$B$1)*(MONTH(Revenue_Log!A6:A5000)=6)*(Revenue_Log!D6:D5000="Other Income")*(Revenue_Log!H6:H5000)) | T14: =IFERROR(S14-R14,"—") | U14: 0 | V14: =SUMPRODUCT((YEAR(Revenue_Log!A6:A5000)=Dashboard!$B$1)*(MONTH(Revenue_Log!A6:A5000)=7)*(Revenue_Log!D6:D5000="Other Income")*(Revenue_Log!H6:H5000)) | W14: =IFERROR(V14-U14,"—") | X14: 0 | Y14: =SUMPRODUCT((YEAR(Revenue_Log!A6:A5000)=Dashboard!$B$1)*(MONTH(Revenue_Log!A6:A5000)=8)*(Revenue_Log!D6:D5000="Other Income")*(Revenue_Log!H6:H5000)) | Z14: =IFERROR(Y14-X14,"—") | AA14: 0 | AB14: =SUMPRODUCT((YEAR(Revenue_Log!A6:A5000)=Dashboard!$B$1)*(MONTH(Revenue_Log!A6:A5000)=9)*(Revenue_Log!D6:D5000="Other Income")*(Revenue_Log!H6:H5000)) | AC14: =IFERROR(AB14-AA14,"—") | AD14: 0 | AE14: =SUMPRODUCT((YEAR(Revenue_Log!A6:A5000)=Dashboard!$B$1)*(MONTH(Revenue_Log!A6:A5000)=10)*(Revenue_Log!D6:D5000="Other Income")*(Revenue_Log!H6:H5000)) | AF14: =IFERROR(AE14-AD14,"—") | AG14: 0 | AH14: =SUMPRODUCT((YEAR(Revenue_Log!A6:A5000)=Dashboard!$B$1)*(MONTH(Revenue_Log!A6:A5000)=11)*(Revenue_Log!D6:D5000="Other Income")*(Revenue_Log!H6:H5000)) | AI14: =IFERROR(AH14-AG14,"—") | AJ14: 0 | AK14: =SUMPRODUCT((YEAR(Revenue_Log!A6:A5000)=Dashboard!$B$1)*(MONTH(Revenue_Log!A6:A5000)=12)*(Revenue_Log!D6:D5000="Other Income")*(Revenue_Log!H6:H5000)) | AL14: =IFERROR(AK14-AJ14,"—") | AM14: =C14+F14+I14+L14+O14+R14+U14+X14+AA14+AD14+AG14+AJ14 | AN14: =D14+G14+J14+M14+P14+S14+V14+Y14+AB14+AE14+AH14+AK14 | AO14: =IFERROR(AN14-AM14,"—")
B15: TOTAL REVENUE | C15: =SUM(C9:C14) | D15: =SUM(D9:D14) | E15: =IFERROR(SUM(E9:E14),"—") | F15: =SUM(F9:F14) | G15: =SUM(G9:G14) | H15: =IFERROR(SUM(H9:H14),"—") | I15: =SUM(I9:I14) | J15: =SUM(J9:J14) | K15: =IFERROR(SUM(K9:K14),"—") | L15: =SUM(L9:L14) | M15: =SUM(M9:M14) | N15: =IFERROR(SUM(N9:N14),"—") | O15: =SUM(O9:O14) | P15: =SUM(P9:P14) | Q15: =IFERROR(SUM(Q9:Q14),"—") | R15: =SUM(R9:R14) | S15: =SUM(S9:S14) | T15: =IFERROR(SUM(T9:T14),"—") | U15: =SUM(U9:U14) | V15: =SUM(V9:V14) | W15: =IFERROR(SUM(W9:W14),"—") | X15: =SUM(X9:X14) | Y15: =SUM(Y9:Y14) | Z15: =IFERROR(SUM(Z9:Z14),"—") | AA15: =SUM(AA9:AA14) | AB15: =SUM(AB9:AB14) | AC15: =IFERROR(SUM(AC9:AC14),"—") | AD15: =SUM(AD9:AD14) | AE15: =SUM(AE9:AE14) | AF15: =IFERROR(SUM(AF9:AF14),"—") | AG15: =SUM(AG9:AG14) | AH15: =SUM(AH9:AH14) | AI15: =IFERROR(SUM(AI9:AI14),"—") | AJ15: =SUM(AJ9:AJ14) | AK15: =SUM(AK9:AK14) | AL15: =IFERROR(SUM(AL9:AL14),"—") | AM15: =SUM(AM9:AM14) | AN15: =SUM(AN9:AN14) | AO15: =IFERROR(SUM(AO9:AO14),"—")
B17: EXPENSE BUDGET
B18: Salaries | C18: 400000 | D18: =SUMPRODUCT((Staff_Salaries!A6:A5000=Dashboard!$B$1)*(Staff_Salaries!B6:B5000="January")*(Staff_Salaries!E6:E5000)) | E18: =IFERROR(C18-D18,"—") | F18: 400000 | G18: =SUMPRODUCT((Staff_Salaries!A6:A5000=Dashboard!$B$1)*(Staff_Salaries!B6:B5000="February")*(Staff_Salaries!E6:E5000)) | H18: =IFERROR(F18-G18,"—") | I18: 400000 | J18: =SUMPRODUCT((Staff_Salaries!A6:A5000=Dashboard!$B$1)*(Staff_Salaries!B6:B5000="March")*(Staff_Salaries!E6:E5000)) | K18: =IFERROR(I18-J18,"—") | L18: 400000 | M18: =SUMPRODUCT((Staff_Salaries!A6:A5000=Dashboard!$B$1)*(Staff_Salaries!B6:B5000="April")*(Staff_Salaries!E6:E5000)) | N18: =IFERROR(L18-M18,"—") | O18: 400000 | P18: =SUMPRODUCT((Staff_Salaries!A6:A5000=Dashboard!$B$1)*(Staff_Salaries!B6:B5000="May")*(Staff_Salaries!E6:E5000)) | Q18: =IFERROR(O18-P18,"—") | R18: 400000 | S18: =SUMPRODUCT((Staff_Salaries!A6:A5000=Dashboard!$B$1)*(Staff_Salaries!B6:B5000="June")*(Staff_Salaries!E6:E5000)) | T18: =IFERROR(R18-S18,"—") | U18: 400000 | V18: =SUMPRODUCT((Staff_Salaries!A6:A5000=Dashboard!$B$1)*(Staff_Salaries!B6:B5000="July")*(Staff_Salaries!E6:E5000)) | W18: =IFERROR(U18-V18,"—") | X18: 400000 | Y18: =SUMPRODUCT((Staff_Salaries!A6:A5000=Dashboard!$B$1)*(Staff_Salaries!B6:B5000="August")*(Staff_Salaries!E6:E5000)) | Z18: =IFERROR(X18-Y18,"—") | AA18: 400000 | AB18: =SUMPRODUCT((Staff_Salaries!A6:A5000=Dashboard!$B$1)*(Staff_Salaries!B6:B5000="September")*(Staff_Salaries!E6:E5000)) | AC18: =IFERROR(AA18-AB18,"—") | AD18: 400000 | AE18: =SUMPRODUCT((Staff_Salaries!A6:A5000=Dashboard!$B$1)*(Staff_Salaries!B6:B5000="October")*(Staff_Salaries!E6:E5000)) | AF18: =IFERROR(AD18-AE18,"—") | AG18: 400000 | AH18: =SUMPRODUCT((Staff_Salaries!A6:A5000=Dashboard!$B$1)*(Staff_Salaries!B6:B5000="November")*(Staff_Salaries!E6:E5000)) | AI18: =IFERROR(AG18-AH18,"—") | AJ18: 400000 | AK18: =SUMPRODUCT((Staff_Salaries!A6:A5000=Dashboard!$B$1)*(Staff_Salaries!B6:B5000="December")*(Staff_Salaries!E6:E5000)) | AL18: =IFERROR(AJ18-AK18,"—") | AM18: =C18+F18+I18+L18+O18+R18+U18+X18+AA18+AD18+AG18+AJ18 | AN18: =D18+G18+J18+M18+P18+S18+V18+Y18+AB18+AE18+AH18+AK18 | AO18: =IFERROR(AM18-AN18,"—")
B19: Construction | C19: 350000 | D19: =SUMPRODUCT((YEAR(Expenses_Log!A6:A5000)=Dashboard!$B$1)*(MONTH(Expenses_Log!A6:A5000)=1)*(Expenses_Log!C6:C5000="Construction")*(Expenses_Log!G6:G5000)) | E19: =IFERROR(C19-D19,"—") | F19: 300000 | G19: =SUMPRODUCT((YEAR(Expenses_Log!A6:A5000)=Dashboard!$B$1)*(MONTH(Expenses_Log!A6:A5000)=2)*(Expenses_Log!C6:C5000="Construction")*(Expenses_Log!G6:G5000)) | H19: =IFERROR(F19-G19,"—") | I19: 250000 | J19: =SUMPRODUCT((YEAR(Expenses_Log!A6:A5000)=Dashboard!$B$1)*(MONTH(Expenses_Log!A6:A5000)=3)*(Expenses_Log!C6:C5000="Construction")*(Expenses_Log!G6:G5000)) | K19: =IFERROR(I19-J19,"—") | L19: 200000 | M19: =SUMPRODUCT((YEAR(Expenses_Log!A6:A5000)=Dashboard!$B$1)*(MONTH(Expenses_Log!A6:A5000)=4)*(Expenses_Log!C6:C5000="Construction")*(Expenses_Log!G6:G5000)) | N19: =IFERROR(L19-M19,"—") | O19: 150000 | P19: =SUMPRODUCT((YEAR(Expenses_Log!A6:A5000)=Dashboard!$B$1)*(MONTH(Expenses_Log!A6:A5000)=5)*(Expenses_Log!C6:C5000="Construction")*(Expenses_Log!G6:G5000)) | Q19: =IFERROR(O19-P19,"—") | R19: 100000 | S19: =SUMPRODUCT((YEAR(Expenses_Log!A6:A5000)=Dashboard!$B$1)*(MONTH(Expenses_Log!A6:A5000)=6)*(Expenses_Log!C6:C5000="Construction")*(Expenses_Log!G6:G5000)) | T19: =IFERROR(R19-S19,"—") | U19: 0 | V19: =SUMPRODUCT((YEAR(Expenses_Log!A6:A5000)=Dashboard!$B$1)*(MONTH(Expenses_Log!A6:A5000)=7)*(Expenses_Log!C6:C5000="Construction")*(Expenses_Log!G6:G5000)) | W19: =IFERROR(U19-V19,"—") | X19: 0 | Y19: =SUMPRODUCT((YEAR(Expenses_Log!A6:A5000)=Dashboard!$B$1)*(MONTH(Expenses_Log!A6:A5000)=8)*(Expenses_Log!C6:C5000="Construction")*(Expenses_Log!G6:G5000)) | Z19: =IFERROR(X19-Y19,"—") | AA19: 0 | AB19: =SUMPRODUCT((YEAR(Expenses_Log!A6:A5000)=Dashboard!$B$1)*(MONTH(Expenses_Log!A6:A5000)=9)*(Expenses_Log!C6:C5000="Construction")*(Expenses_Log!G6:G5000)) | AC19: =IFERROR(AA19-AB19,"—") | AD19: 0 | AE19: =SUMPRODUCT((YEAR(Expenses_Log!A6:A5000)=Dashboard!$B$1)*(MONTH(Expenses_Log!A6:A5000)=10)*(Expenses_Log!C6:C5000="Construction")*(Expenses_Log!G6:G5000)) | AF19: =IFERROR(AD19-AE19,"—") | AG19: 0 | AH19: =SUMPRODUCT((YEAR(Expenses_Log!A6:A5000)=Dashboard!$B$1)*(MONTH(Expenses_Log!A6:A5000)=11)*(Expenses_Log!C6:C5000="Construction")*(Expenses_Log!G6:G5000)) | AI19: =IFERROR(AG19-AH19,"—") | AJ19: 0 | AK19: =SUMPRODUCT((YEAR(Expenses_Log!A6:A5000)=Dashboard!$B$1)*(MONTH(Expenses_Log!A6:A5000)=12)*(Expenses_Log!C6:C5000="Construction")*(Expenses_Log!G6:G5000)) | AL19: =IFERROR(AJ19-AK19,"—") | AM19: =C19+F19+I19+L19+O19+R19+U19+X19+AA19+AD19+AG19+AJ19 | AN19: =D19+G19+J19+M19+P19+S19+V19+Y19+AB19+AE19+AH19+AK19 | AO19: =IFERROR(AM19-AN19,"—")
B20: Maintenance | C20: 100000 | D20: =SUMPRODUCT((YEAR(Expenses_Log!A6:A5000)=Dashboard!$B$1)*(MONTH(Expenses_Log!A6:A5000)=1)*(Expenses_Log!C6:C5000="Maintenance")*(Expenses_Log!G6:G5000)) | E20: =IFERROR(C20-D20,"—") | F20: 90000 | G20: =SUMPRODUCT((YEAR(Expenses_Log!A6:A5000)=Dashboard!$B$1)*(MONTH(Expenses_Log!A6:A5000)=2)*(Expenses_Log!C6:C5000="Maintenance")*(Expenses_Log!G6:G5000)) | H20: =IFERROR(F20-G20,"—") | I20: 90000 | J20: =SUMPRODUCT((YEAR(Expenses_Log!A6:A5000)=Dashboard!$B$1)*(MONTH(Expenses_Log!A6:A5000)=3)*(Expenses_Log!C6:C5000="Maintenance")*(Expenses_Log!G6:G5000)) | K20: =IFERROR(I20-J20,"—") | L20: 80000 | M20: =SUMPRODUCT((YEAR(Expenses_Log!A6:A5000)=Dashboard!$B$1)*(MONTH(Expenses_Log!A6:A5000)=4)*(Expenses_Log!C6:C5000="Maintenance")*(Expenses_Log!G6:G5000)) | N20: =IFERROR(L20-M20,"—") | O20: 80000 | P20: =SUMPRODUCT((YEAR(Expenses_Log!A6:A5000)=Dashboard!$B$1)*(MONTH(Expenses_Log!A6:A5000)=5)*(Expenses_Log!C6:C5000="Maintenance")*(Expenses_Log!G6:G5000)) | Q20: =IFERROR(O20-P20,"—") | R20: 80000 | S20: =SUMPRODUCT((YEAR(Expenses_Log!A6:A5000)=Dashboard!$B$1)*(MONTH(Expenses_Log!A6:A5000)=6)*(Expenses_Log!C6:C5000="Maintenance")*(Expenses_Log!G6:G5000)) | T20: =IFERROR(R20-S20,"—") | U20: 80000 | V20: =SUMPRODUCT((YEAR(Expenses_Log!A6:A5000)=Dashboard!$B$1)*(MONTH(Expenses_Log!A6:A5000)=7)*(Expenses_Log!C6:C5000="Maintenance")*(Expenses_Log!G6:G5000)) | W20: =IFERROR(U20-V20,"—") | X20: 80000 | Y20: =SUMPRODUCT((YEAR(Expenses_Log!A6:A5000)=Dashboard!$B$1)*(MONTH(Expenses_Log!A6:A5000)=8)*(Expenses_Log!C6:C5000="Maintenance")*(Expenses_Log!G6:G5000)) | Z20: =IFERROR(X20-Y20,"—") | AA20: 100000 | AB20: =SUMPRODUCT((YEAR(Expenses_Log!A6:A5000)=Dashboard!$B$1)*(MONTH(Expenses_Log!A6:A5000)=9)*(Expenses_Log!C6:C5000="Maintenance")*(Expenses_Log!G6:G5000)) | AC20: =IFERROR(AA20-AB20,"—") | AD20: 100000 | AE20: =SUMPRODUCT((YEAR(Expenses_Log!A6:A5000)=Dashboard!$B$1)*(MONTH(Expenses_Log!A6:A5000)=10)*(Expenses_Log!C6:C5000="Maintenance")*(Expenses_Log!G6:G5000)) | AF20: =IFERROR(AD20-AE20,"—") | AG20: 90000 | AH20: =SUMPRODUCT((YEAR(Expenses_Log!A6:A5000)=Dashboard!$B$1)*(MONTH(Expenses_Log!A6:A5000)=11)*(Expenses_Log!C6:C5000="Maintenance")*(Expenses_Log!G6:G5000)) | AI20: =IFERROR(AG20-AH20,"—") | AJ20: 90000 | AK20: =SUMPRODUCT((YEAR(Expenses_Log!A6:A5000)=Dashboard!$B$1)*(MONTH(Expenses_Log!A6:A5000)=12)*(Expenses_Log!C6:C5000="Maintenance")*(Expenses_Log!G6:G5000)) | AL20: =IFERROR(AJ20-AK20,"—") | AM20: =C20+F20+I20+L20+O20+R20+U20+X20+AA20+AD20+AG20+AJ20 | AN20: =D20+G20+J20+M20+P20+S20+V20+Y20+AB20+AE20+AH20+AK20 | AO20: =IFERROR(AM20-AN20,"—")
B21: Utilities | C21: 130000 | D21: =SUMPRODUCT((YEAR(Expenses_Log!A6:A5000)=Dashboard!$B$1)*(MONTH(Expenses_Log!A6:A5000)=1)*(Expenses_Log!C6:C5000="Utilities")*(Expenses_Log!G6:G5000)) | E21: =IFERROR(C21-D21,"—") | F21: 120000 | G21: =SUMPRODUCT((YEAR(Expenses_Log!A6:A5000)=Dashboard!$B$1)*(MONTH(Expenses_Log!A6:A5000)=2)*(Expenses_Log!C6:C5000="Utilities")*(Expenses_Log!G6:G5000)) | H21: =IFERROR(F21-G21,"—") | I21: 110000 | J21: =SUMPRODUCT((YEAR(Expenses_Log!A6:A5000)=Dashboard!$B$1)*(MONTH(Expenses_Log!A6:A5000)=3)*(Expenses_Log!C6:C5000="Utilities")*(Expenses_Log!G6:G5000)) | K21: =IFERROR(I21-J21,"—") | L21: 110000 | M21: =SUMPRODUCT((YEAR(Expenses_Log!A6:A5000)=Dashboard!$B$1)*(MONTH(Expenses_Log!A6:A5000)=4)*(Expenses_Log!C6:C5000="Utilities")*(Expenses_Log!G6:G5000)) | N21: =IFERROR(L21-M21,"—") | O21: 110000 | P21: =SUMPRODUCT((YEAR(Expenses_Log!A6:A5000)=Dashboard!$B$1)*(MONTH(Expenses_Log!A6:A5000)=5)*(Expenses_Log!C6:C5000="Utilities")*(Expenses_Log!G6:G5000)) | Q21: =IFERROR(O21-P21,"—") | R21: 110000 | S21: =SUMPRODUCT((YEAR(Expenses_Log!A6:A5000)=Dashboard!$B$1)*(MONTH(Expenses_Log!A6:A5000)=6)*(Expenses_Log!C6:C5000="Utilities")*(Expenses_Log!G6:G5000)) | T21: =IFERROR(R21-S21,"—") | U21: 110000 | V21: =SUMPRODUCT((YEAR(Expenses_Log!A6:A5000)=Dashboard!$B$1)*(MONTH(Expenses_Log!A6:A5000)=7)*(Expenses_Log!C6:C5000="Utilities")*(Expenses_Log!G6:G5000)) | W21: =IFERROR(U21-V21,"—") | X21: 110000 | Y21: =SUMPRODUCT((YEAR(Expenses_Log!A6:A5000)=Dashboard!$B$1)*(MONTH(Expenses_Log!A6:A5000)=8)*(Expenses_Log!C6:C5000="Utilities")*(Expenses_Log!G6:G5000)) | Z21: =IFERROR(X21-Y21,"—") | AA21: 130000 | AB21: =SUMPRODUCT((YEAR(Expenses_Log!A6:A5000)=Dashboard!$B$1)*(MONTH(Expenses_Log!A6:A5000)=9)*(Expenses_Log!C6:C5000="Utilities")*(Expenses_Log!G6:G5000)) | AC21: =IFERROR(AA21-AB21,"—") | AD21: 130000 | AE21: =SUMPRODUCT((YEAR(Expenses_Log!A6:A5000)=Dashboard!$B$1)*(MONTH(Expenses_Log!A6:A5000)=10)*(Expenses_Log!C6:C5000="Utilities")*(Expenses_Log!G6:G5000)) | AF21: =IFERROR(AD21-AE21,"—") | AG21: 120000 | AH21: =SUMPRODUCT((YEAR(Expenses_Log!A6:A5000)=Dashboard!$B$1)*(MONTH(Expenses_Log!A6:A5000)=11)*(Expenses_Log!C6:C5000="Utilities")*(Expenses_Log!G6:G5000)) | AI21: =IFERROR(AG21-AH21,"—") | AJ21: 120000 | AK21: =SUMPRODUCT((YEAR(Expenses_Log!A6:A5000)=Dashboard!$B$1)*(MONTH(Expenses_Log!A6:A5000)=12)*(Expenses_Log!C6:C5000="Utilities")*(Expenses_Log!G6:G5000)) | AL21: =IFERROR(AJ21-AK21,"—") | AM21: =C21+F21+I21+L21+O21+R21+U21+X21+AA21+AD21+AG21+AJ21 | AN21: =D21+G21+J21+M21+P21+S21+V21+Y21+AB21+AE21+AH21+AK21 | AO21: =IFERROR(AM21-AN21,"—")
B22: Inventory | C22: 80000 | D22: =SUMPRODUCT((YEAR(Expenses_Log!A6:A5000)=Dashboard!$B$1)*(MONTH(Expenses_Log!A6:A5000)=1)*(Expenses_Log!C6:C5000="Inventory")*(Expenses_Log!G6:G5000)) | E22: =IFERROR(C22-D22,"—") | F22: 60000 | G22: =SUMPRODUCT((YEAR(Expenses_Log!A6:A5000)=Dashboard!$B$1)*(MONTH(Expenses_Log!A6:A5000)=2)*(Expenses_Log!C6:C5000="Inventory")*(Expenses_Log!G6:G5000)) | H22: =IFERROR(F22-G22,"—") | I22: 60000 | J22: =SUMPRODUCT((YEAR(Expenses_Log!A6:A5000)=Dashboard!$B$1)*(MONTH(Expenses_Log!A6:A5000)=3)*(Expenses_Log!C6:C5000="Inventory")*(Expenses_Log!G6:G5000)) | K22: =IFERROR(I22-J22,"—") | L22: 50000 | M22: =SUMPRODUCT((YEAR(Expenses_Log!A6:A5000)=Dashboard!$B$1)*(MONTH(Expenses_Log!A6:A5000)=4)*(Expenses_Log!C6:C5000="Inventory")*(Expenses_Log!G6:G5000)) | N22: =IFERROR(L22-M22,"—") | O22: 50000 | P22: =SUMPRODUCT((YEAR(Expenses_Log!A6:A5000)=Dashboard!$B$1)*(MONTH(Expenses_Log!A6:A5000)=5)*(Expenses_Log!C6:C5000="Inventory")*(Expenses_Log!G6:G5000)) | Q22: =IFERROR(O22-P22,"—") | R22: 50000 | S22: =SUMPRODUCT((YEAR(Expenses_Log!A6:A5000)=Dashboard!$B$1)*(MONTH(Expenses_Log!A6:A5000)=6)*(Expenses_Log!C6:C5000="Inventory")*(Expenses_Log!G6:G5000)) | T22: =IFERROR(R22-S22,"—") | U22: 50000 | V22: =SUMPRODUCT((YEAR(Expenses_Log!A6:A5000)=Dashboard!$B$1)*(MONTH(Expenses_Log!A6:A5000)=7)*(Expenses_Log!C6:C5000="Inventory")*(Expenses_Log!G6:G5000)) | W22: =IFERROR(U22-V22,"—") | X22: 50000 | Y22: =SUMPRODUCT((YEAR(Expenses_Log!A6:A5000)=Dashboard!$B$1)*(MONTH(Expenses_Log!A6:A5000)=8)*(Expenses_Log!C6:C5000="Inventory")*(Expenses_Log!G6:G5000)) | Z22: =IFERROR(X22-Y22,"—") | AA22: 80000 | AB22: =SUMPRODUCT((YEAR(Expenses_Log!A6:A5000)=Dashboard!$B$1)*(MONTH(Expenses_Log!A6:A5000)=9)*(Expenses_Log!C6:C5000="Inventory")*(Expenses_Log!G6:G5000)) | AC22: =IFERROR(AA22-AB22,"—") | AD22: 80000 | AE22: =SUMPRODUCT((YEAR(Expenses_Log!A6:A5000)=Dashboard!$B$1)*(MONTH(Expenses_Log!A6:A5000)=10)*(Expenses_Log!C6:C5000="Inventory")*(Expenses_Log!G6:G5000)) | AF22: =IFERROR(AD22-AE22,"—") | AG22: 60000 | AH22: =SUMPRODUCT((YEAR(Expenses_Log!A6:A5000)=Dashboard!$B$1)*(MONTH(Expenses_Log!A6:A5000)=11)*(Expenses_Log!C6:C5000="Inventory")*(Expenses_Log!G6:G5000)) | AI22: =IFERROR(AG22-AH22,"—") | AJ22: 60000 | AK22: =SUMPRODUCT((YEAR(Expenses_Log!A6:A5000)=Dashboard!$B$1)*(MONTH(Expenses_Log!A6:A5000)=12)*(Expenses_Log!C6:C5000="Inventory")*(Expenses_Log!G6:G5000)) | AL22: =IFERROR(AJ22-AK22,"—") | AM22: =C22+F22+I22+L22+O22+R22+U22+X22+AA22+AD22+AG22+AJ22 | AN22: =D22+G22+J22+M22+P22+S22+V22+Y22+AB22+AE22+AH22+AK22 | AO22: =IFERROR(AM22-AN22,"—")
B23: Administrative | C23: 40000 | D23: =SUMPRODUCT((YEAR(Expenses_Log!A6:A5000)=Dashboard!$B$1)*(MONTH(Expenses_Log!A6:A5000)=1)*(Expenses_Log!C6:C5000="Administrative")*(Expenses_Log!G6:G5000)) | E23: =IFERROR(C23-D23,"—") | F23: 30000 | G23: =SUMPRODUCT((YEAR(Expenses_Log!A6:A5000)=Dashboard!$B$1)*(MONTH(Expenses_Log!A6:A5000)=2)*(Expenses_Log!C6:C5000="Administrative")*(Expenses_Log!G6:G5000)) | H23: =IFERROR(F23-G23,"—") | I23: 30000 | J23: =SUMPRODUCT((YEAR(Expenses_Log!A6:A5000)=Dashboard!$B$1)*(MONTH(Expenses_Log!A6:A5000)=3)*(Expenses_Log!C6:C5000="Administrative")*(Expenses_Log!G6:G5000)) | K23: =IFERROR(I23-J23,"—") | L23: 25000 | M23: =SUMPRODUCT((YEAR(Expenses_Log!A6:A5000)=Dashboard!$B$1)*(MONTH(Expenses_Log!A6:A5000)=4)*(Expenses_Log!C6:C5000="Administrative")*(Expenses_Log!G6:G5000)) | N23: =IFERROR(L23-M23,"—") | O23: 25000 | P23: =SUMPRODUCT((YEAR(Expenses_Log!A6:A5000)=Dashboard!$B$1)*(MONTH(Expenses_Log!A6:A5000)=5)*(Expenses_Log!C6:C5000="Administrative")*(Expenses_Log!G6:G5000)) | Q23: =IFERROR(O23-P23,"—") | R23: 25000 | S23: =SUMPRODUCT((YEAR(Expenses_Log!A6:A5000)=Dashboard!$B$1)*(MONTH(Expenses_Log!A6:A5000)=6)*(Expenses_Log!C6:C5000="Administrative")*(Expenses_Log!G6:G5000)) | T23: =IFERROR(R23-S23,"—") | U23: 25000 | V23: =SUMPRODUCT((YEAR(Expenses_Log!A6:A5000)=Dashboard!$B$1)*(MONTH(Expenses_Log!A6:A5000)=7)*(Expenses_Log!C6:C5000="Administrative")*(Expenses_Log!G6:G5000)) | W23: =IFERROR(U23-V23,"—") | X23: 25000 | Y23: =SUMPRODUCT((YEAR(Expenses_Log!A6:A5000)=Dashboard!$B$1)*(MONTH(Expenses_Log!A6:A5000)=8)*(Expenses_Log!C6:C5000="Administrative")*(Expenses_Log!G6:G5000)) | Z23: =IFERROR(X23-Y23,"—") | AA23: 40000 | AB23: =SUMPRODUCT((YEAR(Expenses_Log!A6:A5000)=Dashboard!$B$1)*(MONTH(Expenses_Log!A6:A5000)=9)*(Expenses_Log!C6:C5000="Administrative")*(Expenses_Log!G6:G5000)) | AC23: =IFERROR(AA23-AB23,"—") | AD23: 40000 | AE23: =SUMPRODUCT((YEAR(Expenses_Log!A6:A5000)=Dashboard!$B$1)*(MONTH(Expenses_Log!A6:A5000)=10)*(Expenses_Log!C6:C5000="Administrative")*(Expenses_Log!G6:G5000)) | AF23: =IFERROR(AD23-AE23,"—") | AG23: 30000 | AH23: =SUMPRODUCT((YEAR(Expenses_Log!A6:A5000)=Dashboard!$B$1)*(MONTH(Expenses_Log!A6:A5000)=11)*(Expenses_Log!C6:C5000="Administrative")*(Expenses_Log!G6:G5000)) | AI23: =IFERROR(AG23-AH23,"—") | AJ23: 30000 | AK23: =SUMPRODUCT((YEAR(Expenses_Log!A6:A5000)=Dashboard!$B$1)*(MONTH(Expenses_Log!A6:A5000)=12)*(Expenses_Log!C6:C5000="Administrative")*(Expenses_Log!G6:G5000)) | AL23: =IFERROR(AJ23-AK23,"—") | AM23: =C23+F23+I23+L23+O23+R23+U23+X23+AA23+AD23+AG23+AJ23 | AN23: =D23+G23+J23+M23+P23+S23+V23+Y23+AB23+AE23+AH23+AK23 | AO23: =IFERROR(AM23-AN23,"—")
B24: Loans & Advances | C24: 200000 | D24: =SUMPRODUCT((YEAR(Expenses_Log!A6:A5000)=Dashboard!$B$1)*(MONTH(Expenses_Log!A6:A5000)=1)*(Expenses_Log!C6:C5000="Loans & Advances")*(Expenses_Log!G6:G5000)) | E24: =IFERROR(C24-D24,"—") | F24: 0 | G24: =SUMPRODUCT((YEAR(Expenses_Log!A6:A5000)=Dashboard!$B$1)*(MONTH(Expenses_Log!A6:A5000)=2)*(Expenses_Log!C6:C5000="Loans & Advances")*(Expenses_Log!G6:G5000)) | H24: =IFERROR(F24-G24,"—") | I24: 200000 | J24: =SUMPRODUCT((YEAR(Expenses_Log!A6:A5000)=Dashboard!$B$1)*(MONTH(Expenses_Log!A6:A5000)=3)*(Expenses_Log!C6:C5000="Loans & Advances")*(Expenses_Log!G6:G5000)) | K24: =IFERROR(I24-J24,"—") | L24: 0 | M24: =SUMPRODUCT((YEAR(Expenses_Log!A6:A5000)=Dashboard!$B$1)*(MONTH(Expenses_Log!A6:A5000)=4)*(Expenses_Log!C6:C5000="Loans & Advances")*(Expenses_Log!G6:G5000)) | N24: =IFERROR(L24-M24,"—") | O24: 200000 | P24: =SUMPRODUCT((YEAR(Expenses_Log!A6:A5000)=Dashboard!$B$1)*(MONTH(Expenses_Log!A6:A5000)=5)*(Expenses_Log!C6:C5000="Loans & Advances")*(Expenses_Log!G6:G5000)) | Q24: =IFERROR(O24-P24,"—") | R24: 0 | S24: =SUMPRODUCT((YEAR(Expenses_Log!A6:A5000)=Dashboard!$B$1)*(MONTH(Expenses_Log!A6:A5000)=6)*(Expenses_Log!C6:C5000="Loans & Advances")*(Expenses_Log!G6:G5000)) | T24: =IFERROR(R24-S24,"—") | U24: 200000 | V24: =SUMPRODUCT((YEAR(Expenses_Log!A6:A5000)=Dashboard!$B$1)*(MONTH(Expenses_Log!A6:A5000)=7)*(Expenses_Log!C6:C5000="Loans & Advances")*(Expenses_Log!G6:G5000)) | W24: =IFERROR(U24-V24,"—") | X24: 0 | Y24: =SUMPRODUCT((YEAR(Expenses_Log!A6:A5000)=Dashboard!$B$1)*(MONTH(Expenses_Log!A6:A5000)=8)*(Expenses_Log!C6:C5000="Loans & Advances")*(Expenses_Log!G6:G5000)) | Z24: =IFERROR(X24-Y24,"—") | AA24: 200000 | AB24: =SUMPRODUCT((YEAR(Expenses_Log!A6:A5000)=Dashboard!$B$1)*(MONTH(Expenses_Log!A6:A5000)=9)*(Expenses_Log!C6:C5000="Loans & Advances")*(Expenses_Log!G6:G5000)) | AC24: =IFERROR(AA24-AB24,"—") | AD24: 0 | AE24: =SUMPRODUCT((YEAR(Expenses_Log!A6:A5000)=Dashboard!$B$1)*(MONTH(Expenses_Log!A6:A5000)=10)*(Expenses_Log!C6:C5000="Loans & Advances")*(Expenses_Log!G6:G5000)) | AF24: =IFERROR(AD24-AE24,"—") | AG24: 200000 | AH24: =SUMPRODUCT((YEAR(Expenses_Log!A6:A5000)=Dashboard!$B$1)*(MONTH(Expenses_Log!A6:A5000)=11)*(Expenses_Log!C6:C5000="Loans & Advances")*(Expenses_Log!G6:G5000)) | AI24: =IFERROR(AG24-AH24,"—") | AJ24: 0 | AK24: =SUMPRODUCT((YEAR(Expenses_Log!A6:A5000)=Dashboard!$B$1)*(MONTH(Expenses_Log!A6:A5000)=12)*(Expenses_Log!C6:C5000="Loans & Advances")*(Expenses_Log!G6:G5000)) | AL24: =IFERROR(AJ24-AK24,"—") | AM24: =C24+F24+I24+L24+O24+R24+U24+X24+AA24+AD24+AG24+AJ24 | AN24: =D24+G24+J24+M24+P24+S24+V24+Y24+AB24+AE24+AH24+AK24 | AO24: =IFERROR(AM24-AN24,"—")
B25: Transportation | C25: 12000 | D25: =SUMPRODUCT((YEAR(Expenses_Log!A6:A5000)=Dashboard!$B$1)*(MONTH(Expenses_Log!A6:A5000)=1)*(Expenses_Log!C6:C5000="Transportation")*(Expenses_Log!G6:G5000)) | E25: =IFERROR(C25-D25,"—") | F25: 10000 | G25: =SUMPRODUCT((YEAR(Expenses_Log!A6:A5000)=Dashboard!$B$1)*(MONTH(Expenses_Log!A6:A5000)=2)*(Expenses_Log!C6:C5000="Transportation")*(Expenses_Log!G6:G5000)) | H25: =IFERROR(F25-G25,"—") | I25: 10000 | J25: =SUMPRODUCT((YEAR(Expenses_Log!A6:A5000)=Dashboard!$B$1)*(MONTH(Expenses_Log!A6:A5000)=3)*(Expenses_Log!C6:C5000="Transportation")*(Expenses_Log!G6:G5000)) | K25: =IFERROR(I25-J25,"—") | L25: 10000 | M25: =SUMPRODUCT((YEAR(Expenses_Log!A6:A5000)=Dashboard!$B$1)*(MONTH(Expenses_Log!A6:A5000)=4)*(Expenses_Log!C6:C5000="Transportation")*(Expenses_Log!G6:G5000)) | N25: =IFERROR(L25-M25,"—") | O25: 10000 | P25: =SUMPRODUCT((YEAR(Expenses_Log!A6:A5000)=Dashboard!$B$1)*(MONTH(Expenses_Log!A6:A5000)=5)*(Expenses_Log!C6:C5000="Transportation")*(Expenses_Log!G6:G5000)) | Q25: =IFERROR(O25-P25,"—") | R25: 10000 | S25: =SUMPRODUCT((YEAR(Expenses_Log!A6:A5000)=Dashboard!$B$1)*(MONTH(Expenses_Log!A6:A5000)=6)*(Expenses_Log!C6:C5000="Transportation")*(Expenses_Log!G6:G5000)) | T25: =IFERROR(R25-S25,"—") | U25: 10000 | V25: =SUMPRODUCT((YEAR(Expenses_Log!A6:A5000)=Dashboard!$B$1)*(MONTH(Expenses_Log!A6:A5000)=7)*(Expenses_Log!C6:C5000="Transportation")*(Expenses_Log!G6:G5000)) | W25: =IFERROR(U25-V25,"—") | X25: 10000 | Y25: =SUMPRODUCT((YEAR(Expenses_Log!A6:A5000)=Dashboard!$B$1)*(MONTH(Expenses_Log!A6:A5000)=8)*(Expenses_Log!C6:C5000="Transportation")*(Expenses_Log!G6:G5000)) | Z25: =IFERROR(X25-Y25,"—") | AA25: 12000 | AB25: =SUMPRODUCT((YEAR(Expenses_Log!A6:A5000)=Dashboard!$B$1)*(MONTH(Expenses_Log!A6:A5000)=9)*(Expenses_Log!C6:C5000="Transportation")*(Expenses_Log!G6:G5000)) | AC25: =IFERROR(AA25-AB25,"—") | AD25: 12000 | AE25: =SUMPRODUCT((YEAR(Expenses_Log!A6:A5000)=Dashboard!$B$1)*(MONTH(Expenses_Log!A6:A5000)=10)*(Expenses_Log!C6:C5000="Transportation")*(Expenses_Log!G6:G5000)) | AF25: =IFERROR(AD25-AE25,"—") | AG25: 10000 | AH25: =SUMPRODUCT((YEAR(Expenses_Log!A6:A5000)=Dashboard!$B$1)*(MONTH(Expenses_Log!A6:A5000)=11)*(Expenses_Log!C6:C5000="Transportation")*(Expenses_Log!G6:G5000)) | AI25: =IFERROR(AG25-AH25,"—") | AJ25: 10000 | AK25: =SUMPRODUCT((YEAR(Expenses_Log!A6:A5000)=Dashboard!$B$1)*(MONTH(Expenses_Log!A6:A5000)=12)*(Expenses_Log!C6:C5000="Transportation")*(Expenses_Log!G6:G5000)) | AL25: =IFERROR(AJ25-AK25,"—") | AM25: =C25+F25+I25+L25+O25+R25+U25+X25+AA25+AD25+AG25+AJ25 | AN25: =D25+G25+J25+M25+P25+S25+V25+Y25+AB25+AE25+AH25+AK25 | AO25: =IFERROR(AM25-AN25,"—")
B26: IT & Communications | C26: 15000 | D26: =SUMPRODUCT((YEAR(Expenses_Log!A6:A5000)=Dashboard!$B$1)*(MONTH(Expenses_Log!A6:A5000)=1)*(Expenses_Log!C6:C5000="IT & Communications")*(Expenses_Log!G6:G5000)) | E26: =IFERROR(C26-D26,"—") | F26: 12000 | G26: =SUMPRODUCT((YEAR(Expenses_Log!A6:A5000)=Dashboard!$B$1)*(MONTH(Expenses_Log!A6:A5000)=2)*(Expenses_Log!C6:C5000="IT & Communications")*(Expenses_Log!G6:G5000)) | H26: =IFERROR(F26-G26,"—") | I26: 12000 | J26: =SUMPRODUCT((YEAR(Expenses_Log!A6:A5000)=Dashboard!$B$1)*(MONTH(Expenses_Log!A6:A5000)=3)*(Expenses_Log!C6:C5000="IT & Communications")*(Expenses_Log!G6:G5000)) | K26: =IFERROR(I26-J26,"—") | L26: 10000 | M26: =SUMPRODUCT((YEAR(Expenses_Log!A6:A5000)=Dashboard!$B$1)*(MONTH(Expenses_Log!A6:A5000)=4)*(Expenses_Log!C6:C5000="IT & Communications")*(Expenses_Log!G6:G5000)) | N26: =IFERROR(L26-M26,"—") | O26: 10000 | P26: =SUMPRODUCT((YEAR(Expenses_Log!A6:A5000)=Dashboard!$B$1)*(MONTH(Expenses_Log!A6:A5000)=5)*(Expenses_Log!C6:C5000="IT & Communications")*(Expenses_Log!G6:G5000)) | Q26: =IFERROR(O26-P26,"—") | R26: 10000 | S26: =SUMPRODUCT((YEAR(Expenses_Log!A6:A5000)=Dashboard!$B$1)*(MONTH(Expenses_Log!A6:A5000)=6)*(Expenses_Log!C6:C5000="IT & Communications")*(Expenses_Log!G6:G5000)) | T26: =IFERROR(R26-S26,"—") | U26: 10000 | V26: =SUMPRODUCT((YEAR(Expenses_Log!A6:A5000)=Dashboard!$B$1)*(MONTH(Expenses_Log!A6:A5000)=7)*(Expenses_Log!C6:C5000="IT & Communications")*(Expenses_Log!G6:G5000)) | W26: =IFERROR(U26-V26,"—") | X26: 10000 | Y26: =SUMPRODUCT((YEAR(Expenses_Log!A6:A5000)=Dashboard!$B$1)*(MONTH(Expenses_Log!A6:A5000)=8)*(Expenses_Log!C6:C5000="IT & Communications")*(Expenses_Log!G6:G5000)) | Z26: =IFERROR(X26-Y26,"—") | AA26: 15000 | AB26: =SUMPRODUCT((YEAR(Expenses_Log!A6:A5000)=Dashboard!$B$1)*(MONTH(Expenses_Log!A6:A5000)=9)*(Expenses_Log!C6:C5000="IT & Communications")*(Expenses_Log!G6:G5000)) | AC26: =IFERROR(AA26-AB26,"—") | AD26: 15000 | AE26: =SUMPRODUCT((YEAR(Expenses_Log!A6:A5000)=Dashboard!$B$1)*(MONTH(Expenses_Log!A6:A5000)=10)*(Expenses_Log!C6:C5000="IT & Communications")*(Expenses_Log!G6:G5000)) | AF26: =IFERROR(AD26-AE26,"—") | AG26: 12000 | AH26: =SUMPRODUCT((YEAR(Expenses_Log!A6:A5000)=Dashboard!$B$1)*(MONTH(Expenses_Log!A6:A5000)=11)*(Expenses_Log!C6:C5000="IT & Communications")*(Expenses_Log!G6:G5000)) | AI26: =IFERROR(AG26-AH26,"—") | AJ26: 12000 | AK26: =SUMPRODUCT((YEAR(Expenses_Log!A6:A5000)=Dashboard!$B$1)*(MONTH(Expenses_Log!A6:A5000)=12)*(Expenses_Log!C6:C5000="IT & Communications")*(Expenses_Log!G6:G5000)) | AL26: =IFERROR(AJ26-AK26,"—") | AM26: =C26+F26+I26+L26+O26+R26+U26+X26+AA26+AD26+AG26+AJ26 | AN26: =D26+G26+J26+M26+P26+S26+V26+Y26+AB26+AE26+AH26+AK26 | AO26: =IFERROR(AM26-AN26,"—")
B27: Other | C27: 10000 | D27: =SUMPRODUCT((YEAR(Expenses_Log!A6:A5000)=Dashboard!$B$1)*(MONTH(Expenses_Log!A6:A5000)=1)*(Expenses_Log!C6:C5000="Other")*(Expenses_Log!G6:G5000)) | E27: =IFERROR(C27-D27,"—") | F27: 8000 | G27: =SUMPRODUCT((YEAR(Expenses_Log!A6:A5000)=Dashboard!$B$1)*(MONTH(Expenses_Log!A6:A5000)=2)*(Expenses_Log!C6:C5000="Other")*(Expenses_Log!G6:G5000)) | H27: =IFERROR(F27-G27,"—") | I27: 8000 | J27: =SUMPRODUCT((YEAR(Expenses_Log!A6:A5000)=Dashboard!$B$1)*(MONTH(Expenses_Log!A6:A5000)=3)*(Expenses_Log!C6:C5000="Other")*(Expenses_Log!G6:G5000)) | K27: =IFERROR(I27-J27,"—") | L27: 8000 | M27: =SUMPRODUCT((YEAR(Expenses_Log!A6:A5000)=Dashboard!$B$1)*(MONTH(Expenses_Log!A6:A5000)=4)*(Expenses_Log!C6:C5000="Other")*(Expenses_Log!G6:G5000)) | N27: =IFERROR(L27-M27,"—") | O27: 8000 | P27: =SUMPRODUCT((YEAR(Expenses_Log!A6:A5000)=Dashboard!$B$1)*(MONTH(Expenses_Log!A6:A5000)=5)*(Expenses_Log!C6:C5000="Other")*(Expenses_Log!G6:G5000)) | Q27: =IFERROR(O27-P27,"—") | R27: 8000 | S27: =SUMPRODUCT((YEAR(Expenses_Log!A6:A5000)=Dashboard!$B$1)*(MONTH(Expenses_Log!A6:A5000)=6)*(Expenses_Log!C6:C5000="Other")*(Expenses_Log!G6:G5000)) | T27: =IFERROR(R27-S27,"—") | U27: 8000 | V27: =SUMPRODUCT((YEAR(Expenses_Log!A6:A5000)=Dashboard!$B$1)*(MONTH(Expenses_Log!A6:A5000)=7)*(Expenses_Log!C6:C5000="Other")*(Expenses_Log!G6:G5000)) | W27: =IFERROR(U27-V27,"—") | X27: 8000 | Y27: =SUMPRODUCT((YEAR(Expenses_Log!A6:A5000)=Dashboard!$B$1)*(MONTH(Expenses_Log!A6:A5000)=8)*(Expenses_Log!C6:C5000="Other")*(Expenses_Log!G6:G5000)) | Z27: =IFERROR(X27-Y27,"—") | AA27: 10000 | AB27: =SUMPRODUCT((YEAR(Expenses_Log!A6:A5000)=Dashboard!$B$1)*(MONTH(Expenses_Log!A6:A5000)=9)*(Expenses_Log!C6:C5000="Other")*(Expenses_Log!G6:G5000)) | AC27: =IFERROR(AA27-AB27,"—") | AD27: 10000 | AE27: =SUMPRODUCT((YEAR(Expenses_Log!A6:A5000)=Dashboard!$B$1)*(MONTH(Expenses_Log!A6:A5000)=10)*(Expenses_Log!C6:C5000="Other")*(Expenses_Log!G6:G5000)) | AF27: =IFERROR(AD27-AE27,"—") | AG27: 8000 | AH27: =SUMPRODUCT((YEAR(Expenses_Log!A6:A5000)=Dashboard!$B$1)*(MONTH(Expenses_Log!A6:A5000)=11)*(Expenses_Log!C6:C5000="Other")*(Expenses_Log!G6:G5000)) | AI27: =IFERROR(AG27-AH27,"—") | AJ27: 8000 | AK27: =SUMPRODUCT((YEAR(Expenses_Log!A6:A5000)=Dashboard!$B$1)*(MONTH(Expenses_Log!A6:A5000)=12)*(Expenses_Log!C6:C5000="Other")*(Expenses_Log!G6:G5000)) | AL27: =IFERROR(AJ27-AK27,"—") | AM27: =C27+F27+I27+L27+O27+R27+U27+X27+AA27+AD27+AG27+AJ27 | AN27: =D27+G27+J27+M27+P27+S27+V27+Y27+AB27+AE27+AH27+AK27 | AO27: =IFERROR(AM27-AN27,"—")
B28: TOTAL EXPENSES | C28: =SUM(C18:C27) | D28: =SUM(D18:D27) | E28: =IFERROR(SUM(E18:E27),"—") | F28: =SUM(F18:F27) | G28: =SUM(G18:G27) | H28: =IFERROR(SUM(H18:H27),"—") | I28: =SUM(I18:I27) | J28: =SUM(J18:J27) | K28: =IFERROR(SUM(K18:K27),"—") | L28: =SUM(L18:L27) | M28: =SUM(M18:M27) | N28: =IFERROR(SUM(N18:N27),"—") | O28: =SUM(O18:O27) | P28: =SUM(P18:P27) | Q28: =IFERROR(SUM(Q18:Q27),"—") | R28: =SUM(R18:R27) | S28: =SUM(S18:S27) | T28: =IFERROR(SUM(T18:T27),"—") | U28: =SUM(U18:U27) | V28: =SUM(V18:V27) | W28: =IFERROR(SUM(W18:W27),"—") | X28: =SUM(X18:X27) | Y28: =SUM(Y18:Y27) | Z28: =IFERROR(SUM(Z18:Z27),"—") | AA28: =SUM(AA18:AA27) | AB28: =SUM(AB18:AB27) | AC28: =IFERROR(SUM(AC18:AC27),"—") | AD28: =SUM(AD18:AD27) | AE28: =SUM(AE18:AE27) | AF28: =IFERROR(SUM(AF18:AF27),"—") | AG28: =SUM(AG18:AG27) | AH28: =SUM(AH18:AH27) | AI28: =IFERROR(SUM(AI18:AI27),"—") | AJ28: =SUM(AJ18:AJ27) | AK28: =SUM(AK18:AK27) | AL28: =IFERROR(SUM(AL18:AL27),"—") | AM28: =SUM(AM18:AM27) | AN28: =SUM(AN18:AN27) | AO28: =IFERROR(SUM(AO18:AO27),"—")
B29: NET PROFIT | C29: =C15-C28 | D29: =D15-D28 | E29: =IFERROR(E15-E28,"—") | F29: =F15-F28 | G29: =G15-G28 | H29: =IFERROR(H15-H28,"—") | I29: =I15-I28 | J29: =J15-J28 | K29: =IFERROR(K15-K28,"—") | L29: =L15-L28 | M29: =M15-M28 | N29: =IFERROR(N15-N28,"—") | O29: =O15-O28 | P29: =P15-P28 | Q29: =IFERROR(Q15-Q28,"—") | R29: =R15-R28 | S29: =S15-S28 | T29: =IFERROR(T15-T28,"—") | U29: =U15-U28 | V29: =V15-V28 | W29: =IFERROR(W15-W28,"—") | X29: =X15-X28 | Y29: =Y15-Y28 | Z29: =IFERROR(Z15-Z28,"—") | AA29: =AA15-AA28 | AB29: =AB15-AB28 | AC29: =IFERROR(AC15-AC28,"—") | AD29: =AD15-AD28 | AE29: =AE15-AE28 | AF29: =IFERROR(AF15-AF28,"—") | AG29: =AG15-AG28 | AH29: =AH15-AH28 | AI29: =IFERROR(AI15-AI28,"—") | AJ29: =AJ15-AJ28 | AK29: =AK15-AK28 | AL29: =IFERROR(AL15-AL28,"—") | AM29: =AM15-AM28 | AN29: =AN15-AN28 | AO29: =IFERROR(AO15-AO28,"—")

Sheet Dashboard
A1: FY Year: | B1: 2024
E2: TALENTS APARTMENT
E3: ="Executive Dashboard | FY "&Dashboard!$B$1
B5: FILTER: | C5: All
B7: TOTAL REVENUE | E7: TOTAL EXPENSES | H7: NET PROFIT | K7: STAFF SALARIES | N7: MARGIN
B8: =IF(C5="All",SUMPRODUCT((YEAR(Revenue_Log!A6:A5000)=Dashboard!$B$1)*(Revenue_Log!H6:H5000)),SUMPRODUCT((YEAR(Revenue_Log!A6:A5000)=Dashboard!$B$1)*(Revenue_Log!B6:B5000=C5)*(Revenue_Log!H6:H5000))) | E8: =IFERROR(IF(C5="All",SUMPRODUCT((YEAR(Expenses_Log!A6:A5000)=Dashboard!$B$1)*(Expenses_Log!G6:G5000))+Staff_Salaries!E4,SUMPRODUCT((YEAR(Expenses_Log!A6:A5000)=Dashboard!$B$1)*(Expenses_Log!B6:B5000=C5)*(Expenses_Log!G6:G5000))+Staff_Salaries!E4),"—") | H8: =B8-E8 | K8: =Staff_Salaries!E4 | N8: =IFERROR(H8/B8,0)
B10: REVENUE & EXPENDITURE
C11: Jan | D11: Feb | E11: Mar | F11: Apr | G11: May | H11: Jun | I11: Jul | J11: Aug | K11: Sep | L11: Oct | M11: Nov | N11: Dec | O11: YTD
B12: REVENUE:
B13: Room Revenue | C13: =IF($C$5="All",SUMPRODUCT((MONTH(Revenue_Log!A6:A5000)=1)*(Revenue_Log!D6:D5000="Room Revenue")*(Revenue_Log!H6:H5000)),SUMPRODUCT((MONTH(Revenue_Log!A6:A5000)=1)*(Revenue_Log!D6:D5000="Room Revenue")*(Revenue_Log!B6:B5000=$C$5)*(Revenue_Log!H6:H5000))) | D13: =IF($C$5="All",SUMPRODUCT((MONTH(Revenue_Log!A6:A5000)=2)*(Revenue_Log!D6:D5000="Room Revenue")*(Revenue_Log!H6:H5000)),SUMPRODUCT((MONTH(Revenue_Log!A6:A5000)=2)*(Revenue_Log!D6:D5000="Room Revenue")*(Revenue_Log!B6:B5000=$C$5)*(Revenue_Log!H6:H5000))) | E13: =IF($C$5="All",SUMPRODUCT((MONTH(Revenue_Log!A6:A5000)=3)*(Revenue_Log!D6:D5000="Room Revenue")*(Revenue_Log!H6:H5000)),SUMPRODUCT((MONTH(Revenue_Log!A6:A5000)=3)*(Revenue_Log!D6:D5000="Room Revenue")*(Revenue_Log!B6:B5000=$C$5)*(Revenue_Log!H6:H5000))) | F13: =IF($C$5="All",SUMPRODUCT((MONTH(Revenue_Log!A6:A5000)=4)*(Revenue_Log!D6:D5000="Room Revenue")*(Revenue_Log!H6:H5000)),SUMPRODUCT((MONTH(Revenue_Log!A6:A5000)=4)*(Revenue_Log!D6:D5000="Room Revenue")*(Revenue_Log!B6:B5000=$C$5)*(Revenue_Log!H6:H5000))) | G13: =IF($C$5="All",SUMPRODUCT((MONTH(Revenue_Log!A6:A5000)=5)*(Revenue_Log!D6:D5000="Room Revenue")*(Revenue_Log!H6:H5000)),SUMPRODUCT((MONTH(Revenue_Log!A6:A5000)=5)*(Revenue_Log!D6:D5000="Room Revenue")*(Revenue_Log!B6:B5000=$C$5)*(Revenue_Log!H6:H5000))) | H13: =IF($C$5="All",SUMPRODUCT((MONTH(Revenue_Log!A6:A5000)=6)*(Revenue_Log!D6:D5000="Room Revenue")*(Revenue_Log!H6:H5000)),SUMPRODUCT((MONTH(Revenue_Log!A6:A5000)=6)*(Revenue_Log!D6:D5000="Room Revenue")*(Revenue_Log!B6:B5000=$C$5)*(Revenue_Log!H6:H5000))) | I13: =IF($C$5="All",SUMPRODUCT((MONTH(Revenue_Log!A6:A5000)=7)*(Revenue_Log!D6:D5000="Room Revenue")*(Revenue_Log!H6:H5000)),SUMPRODUCT((MONTH(Revenue_Log!A6:A5000)=7)*(Revenue_Log!D6:D5000="Room Revenue")*(Revenue_Log!B6:B5000=$C$5)*(Revenue_Log!H6:H5000))) | J13: =IF($C$5="All",SUMPRODUCT((MONTH(Revenue_Log!A6:A5000)=8)*(Revenue_Log!D6:D5000="Room Revenue")*(Revenue_Log!H6:H5000)),SUMPRODUCT((MONTH(Revenue_Log!A6:A5000)=8)*(Revenue_Log!D6:D5000="Room Revenue")*(Revenue_Log!B6:B5000=$C$5)*(Revenue_Log!H6:H5000))) | K13: =IF($C$5="All",SUMPRODUCT((MONTH(Revenue_Log!A6:A5000)=9)*(Revenue_Log!D6:D5000="Room Revenue")*(Revenue_Log!H6:H5000)),SUMPRODUCT((MONTH(Revenue_Log!A6:A5000)=9)*(Revenue_Log!D6:D5000="Room Revenue")*(Revenue_Log!B6:B5000=$C$5)*(Revenue_Log!H6:H5000))) | L13: =IF($C$5="All",SUMPRODUCT((MONTH(Revenue_Log!A6:A5000)=10)*(Revenue_Log!D6:D5000="Room Revenue")*(Revenue_Log!H6:H5000)),SUMPRODUCT((MONTH(Revenue_Log!A6:A5000)=10)*(Revenue_Log!D6:D5000="Room Revenue")*(Revenue_Log!B6:B5000=$C$5)*(Revenue_Log!H6:H5000))) | M13: =IF($C$5="All",SUMPRODUCT((MONTH(Revenue_Log!A6:A5000)=11)*(Revenue_Log!D6:D5000="Room Revenue")*(Revenue_Log!H6:H5000)),SUMPRODUCT((MONTH(Revenue_Log!A6:A5000)=11)*(Revenue_Log!D6:D5000="Room Revenue")*(Revenue_Log!B6:B5000=$C$5)*(Revenue_Log!H6:H5000))) | N13: =IF($C$5="All",SUMPRODUCT((MONTH(Revenue_Log!A6:A5000)=12)*(Revenue_Log!D6:D5000="Room Revenue")*(Revenue_Log!H6:H5000)),SUMPRODUCT((MONTH(Revenue_Log!A6:A5000)=12)*(Revenue_Log!D6:D5000="Room Revenue")*(Revenue_Log!B6:B5000=$C$5)*(Revenue_Log!H6:H5000))) | O13: =SUM(C13:N13)
B14: Shop Rent | C14: =IF($C$5="All",SUMPRODUCT((MONTH(Revenue_Log!A6:A5000)=1)*(Revenue_Log!D6:D5000="Shop Rent")*(Revenue_Log!H6:H5000)),SUMPRODUCT((MONTH(Revenue_Log!A6:A5000)=1)*(Revenue_Log!D6:D5000="Shop Rent")*(Revenue_Log!B6:B5000=$C$5)*(Revenue_Log!H6:H5000))) | D14: =IF($C$5="All",SUMPRODUCT((MONTH(Revenue_Log!A6:A5000)=2)*(Revenue_Log!D6:D5000="Shop Rent")*(Revenue_Log!H6:H5000)),SUMPRODUCT((MONTH(Revenue_Log!A6:A5000)=2)*(Revenue_Log!D6:D5000="Shop Rent")*(Revenue_Log!B6:B5000=$C$5)*(Revenue_Log!H6:H5000))) | E14: =IF($C$5="All",SUMPRODUCT((MONTH(Revenue_Log!A6:A5000)=3)*(Revenue_Log!D6:D5000="Shop Rent")*(Revenue_Log!H6:H5000)),SUMPRODUCT((MONTH(Revenue_Log!A6:A5000)=3)*(Revenue_Log!D6:D5000="Shop Rent")*(Revenue_Log!B6:B5000=$C$5)*(Revenue_Log!H6:H5000))) | F14: =IF($C$5="All",SUMPRODUCT((MONTH(Revenue_Log!A6:A5000)=4)*(Revenue_Log!D6:D5000="Shop Rent")*(Revenue_Log!H6:H5000)),SUMPRODUCT((MONTH(Revenue_Log!A6:A5000)=4)*(Revenue_Log!D6:D5000="Shop Rent")*(Revenue_Log!B6:B5000=$C$5)*(Revenue_Log!H6:H5000))) | G14: =IF($C$5="All",SUMPRODUCT((MONTH(Revenue_Log!A6:A5000)=5)*(Revenue_Log!D6:D5000="Shop Rent")*(Revenue_Log!H6:H5000)),SUMPRODUCT((MONTH(Revenue_Log!A6:A5000)=5)*(Revenue_Log!D6:D5000="Shop Rent")*(Revenue_Log!B6:B5000=$C$5)*(Revenue_Log!H6:H5000))) | H14: =IF($C$5="All",SUMPRODUCT((MONTH(Revenue_Log!A6:A5000)=6)*(Revenue_Log!D6:D5000="Shop Rent")*(Revenue_Log!H6:H5000)),SUMPRODUCT((MONTH(Revenue_Log!A6:A5000)=6)*(Revenue_Log!D6:D5000="Shop Rent")*(Revenue_Log!B6:B5000=$C$5)*(Revenue_Log!H6:H5000))) | I14: =IF($C$5="All",SUMPRODUCT((MONTH(Revenue_Log!A6:A5000)=7)*(Revenue_Log!D6:D5000="Shop Rent")*(Revenue_Log!H6:H5000)),SUMPRODUCT((MONTH(Revenue_Log!A6:A5000)=7)*(Revenue_Log!D6:D5000="Shop Rent")*(Revenue_Log!B6:B5000=$C$5)*(Revenue_Log!H6:H5000))) | J14: =IF($C$5="All",SUMPRODUCT((MONTH(Revenue_Log!A6:A5000)=8)*(Revenue_Log!D6:D5000="Shop Rent")*(Revenue_Log!H6:H5000)),SUMPRODUCT((MONTH(Revenue_Log!A6:A5000)=8)*(Revenue_Log!D6:D5000="Shop Rent")*(Revenue_Log!B6:B5000=$C$5)*(Revenue_Log!H6:H5000))) | K14: =IF($C$5="All",SUMPRODUCT((MONTH(Revenue_Log!A6:A5000)=9)*(Revenue_Log!D6:D5000="Shop Rent")*(Revenue_Log!H6:H5000)),SUMPRODUCT((MONTH(Revenue_Log!A6:A5000)=9)*(Revenue_Log!D6:D5000="Shop Rent")*(Revenue_Log!B6:B5000=$C$5)*(Revenue_Log!H6:H5000))) | L14: =IF($C$5="All",SUMPRODUCT((MONTH(Revenue_Log!A6:A5000)=10)*(Revenue_Log!D6:D5000="Shop Rent")*(Revenue_Log!H6:H5000)),SUMPRODUCT((MONTH(Revenue_Log!A6:A5000)=10)*(Revenue_Log!D6:D5000="Shop Rent")*(Revenue_Log!B6:B5000=$C$5)*(Revenue_Log!H6:H5000))) | M14: =IF($C$5="All",SUMPRODUCT((MONTH(Revenue_Log!A6:A5000)=11)*(Revenue_Log!D6:D5000="Shop Rent")*(Revenue_Log!H6:H5000)),SUMPRODUCT((MONTH(Revenue_Log!A6:A5000)=11)*(Revenue_Log!D6:D5000="Shop Rent")*(Revenue_Log!B6:B5000=$C$5)*(Revenue_Log!H6:H5000))) | N14: =IF($C$5="All",SUMPRODUCT((MONTH(Revenue_Log!A6:A5000)=12)*(Revenue_Log!D6:D5000="Shop Rent")*(Revenue_Log!H6:H5000)),SUMPRODUCT((MONTH(Revenue_Log!A6:A5000)=12)*(Revenue_Log!D6:D5000="Shop Rent")*(Revenue_Log!B6:B5000=$C$5)*(Revenue_Log!H6:H5000))) | O14: =SUM(C14:N14)
